[2021-05-17 00:35:51,095] {taskinstance.py:669} INFO - Dependencies all met for <TaskInstance: bigquery_data_load.list_files 2021-05-16T19:33:21.835513+00:00 [queued]>
[2021-05-17 00:35:51,102] {taskinstance.py:669} INFO - Dependencies all met for <TaskInstance: bigquery_data_load.list_files 2021-05-16T19:33:21.835513+00:00 [queued]>
[2021-05-17 00:35:51,103] {taskinstance.py:879} INFO - 
--------------------------------------------------------------------------------
[2021-05-17 00:35:51,103] {taskinstance.py:880} INFO - Starting attempt 1 of 1
[2021-05-17 00:35:51,103] {taskinstance.py:881} INFO - 
--------------------------------------------------------------------------------
[2021-05-17 00:35:51,129] {taskinstance.py:900} INFO - Executing <Task(PythonOperator): list_files> on 2021-05-16T19:33:21.835513+00:00
[2021-05-17 00:35:51,133] {standard_task_runner.py:53} INFO - Started process 28723 to run task
[2021-05-17 00:35:51,218] {logging_mixin.py:112} INFO - Running %s on host %s <TaskInstance: bigquery_data_load.list_files 2021-05-16T19:33:21.835513+00:00 [running]> alieymsxxn
[2021-05-17 00:35:52,400] {taskinstance.py:1145} ERROR - 404 GET https://storage.googleapis.com/storage/v1/b/ma-logistcis/o?projection=noAcl&prettyPrint=false: Not Found
Traceback (most recent call last):
  File "/home/alieymsxxn/anaconda3/envs/airflow/lib/python3.7/site-packages/airflow/models/taskinstance.py", line 983, in _run_raw_task
    result = task_copy.execute(context=context)
  File "/home/alieymsxxn/anaconda3/envs/airflow/lib/python3.7/site-packages/airflow/operators/python_operator.py", line 113, in execute
    return_value = self.execute_callable()
  File "/home/alieymsxxn/anaconda3/envs/airflow/lib/python3.7/site-packages/airflow/operators/python_operator.py", line 118, in execute_callable
    return self.python_callable(*self.op_args, **self.op_kwargs)
  File "/home/alieymsxxn/Documents/Projects/airflow/airflow_home/dags/bigquery_data_load.py", line 21, in list_objects
    storage_objects = hook.list(bucket)
  File "/home/alieymsxxn/anaconda3/envs/airflow/lib/python3.7/site-packages/airflow/contrib/hooks/gcs_hook.py", line 330, in list
    for blob in blobs:
  File "/home/alieymsxxn/anaconda3/envs/airflow/lib/python3.7/site-packages/google/api_core/page_iterator.py", line 212, in _items_iter
    for page in self._page_iter(increment=False):
  File "/home/alieymsxxn/anaconda3/envs/airflow/lib/python3.7/site-packages/google/api_core/page_iterator.py", line 243, in _page_iter
    page = self._next_page()
  File "/home/alieymsxxn/anaconda3/envs/airflow/lib/python3.7/site-packages/google/api_core/page_iterator.py", line 369, in _next_page
    response = self._get_next_page_response()
  File "/home/alieymsxxn/anaconda3/envs/airflow/lib/python3.7/site-packages/google/api_core/page_iterator.py", line 419, in _get_next_page_response
    method=self._HTTP_METHOD, path=self.path, query_params=params
  File "/home/alieymsxxn/anaconda3/envs/airflow/lib/python3.7/site-packages/google/cloud/storage/_http.py", line 78, in api_request
    return call()
  File "/home/alieymsxxn/anaconda3/envs/airflow/lib/python3.7/site-packages/google/api_core/retry.py", line 286, in retry_wrapped_func
    on_error=on_error,
  File "/home/alieymsxxn/anaconda3/envs/airflow/lib/python3.7/site-packages/google/api_core/retry.py", line 184, in retry_target
    return target()
  File "/home/alieymsxxn/anaconda3/envs/airflow/lib/python3.7/site-packages/google/cloud/_http.py", line 483, in api_request
    raise exceptions.from_http_response(response)
google.api_core.exceptions.NotFound: 404 GET https://storage.googleapis.com/storage/v1/b/ma-logistcis/o?projection=noAcl&prettyPrint=false: Not Found
[2021-05-17 00:35:52,409] {taskinstance.py:1202} INFO - Marking task as FAILED.dag_id=bigquery_data_load, task_id=list_files, execution_date=20210516T193321, start_date=20210516T193551, end_date=20210516T193552
[2021-05-17 00:36:01,048] {logging_mixin.py:112} INFO - [2021-05-17 00:36:01,047] {local_task_job.py:103} INFO - Task exited with return code 1
