[2021-05-17 03:00:41,165] {taskinstance.py:669} INFO - Dependencies all met for <TaskInstance: bigquery_data_load.load_data 2021-05-16T21:00:00+00:00 [queued]>
[2021-05-17 03:00:41,184] {taskinstance.py:669} INFO - Dependencies all met for <TaskInstance: bigquery_data_load.load_data 2021-05-16T21:00:00+00:00 [queued]>
[2021-05-17 03:00:41,184] {taskinstance.py:879} INFO - 
--------------------------------------------------------------------------------
[2021-05-17 03:00:41,184] {taskinstance.py:880} INFO - Starting attempt 1 of 1
[2021-05-17 03:00:41,184] {taskinstance.py:881} INFO - 
--------------------------------------------------------------------------------
[2021-05-17 03:00:41,222] {taskinstance.py:900} INFO - Executing <Task(GoogleCloudStorageToBigQueryOperator): load_data> on 2021-05-16T21:00:00+00:00
[2021-05-17 03:00:41,225] {standard_task_runner.py:53} INFO - Started process 37421 to run task
[2021-05-17 03:00:41,334] {logging_mixin.py:112} INFO - Running %s on host %s <TaskInstance: bigquery_data_load.load_data 2021-05-16T21:00:00+00:00 [running]> alieymsxxn
[2021-05-17 03:00:49,375] {taskinstance.py:1145} ERROR - BigQuery job failed. Final error was: {'reason': 'invalid', 'location': 'gs://ma-logistics/4649493c.csv', 'message': "Error while reading data, error message: Could not parse '27.981478ta2' as DOUBLE for field longitude (position 5) starting at location 298  with message 'Unable to parse'"}. The job was: {'kind': 'bigquery#job', 'etag': '0kVa6CkfZGFNoEjw+q67NA==', 'id': 'ma-airflow:asia-south1.job_Qe-8uiKwCp_Dfg-8WJyCUiRKzJlW', 'selfLink': 'https://bigquery.googleapis.com/bigquery/v2/projects/ma-airflow/jobs/job_Qe-8uiKwCp_Dfg-8WJyCUiRKzJlW?location=asia-south1', 'user_email': 'airflow@ma-airflow.iam.gserviceaccount.com', 'configuration': {'load': {'sourceUris': ['gs://ma-logistics/*'], 'destinationTable': {'projectId': 'ma-airflow', 'datasetId': 'analytics', 'tableId': 'history'}, 'createDisposition': 'CREATE_IF_NEEDED', 'writeDisposition': 'WRITE_APPEND', 'fieldDelimiter': ',', 'skipLeadingRows': 1, 'encoding': 'UTF-8', 'allowQuotedNewlines': False, 'sourceFormat': 'CSV', 'ignoreUnknownValues': False, 'autodetect': True}, 'jobType': 'LOAD'}, 'jobReference': {'projectId': 'ma-airflow', 'jobId': 'job_Qe-8uiKwCp_Dfg-8WJyCUiRKzJlW', 'location': 'asia-south1'}, 'statistics': {'creationTime': '1621202446777', 'startTime': '1621202446973', 'endTime': '1621202447917', 'load': {}, 'totalSlotMs': '158', 'reservation_id': 'default-pipeline'}, 'status': {'errorResult': {'reason': 'invalid', 'location': 'gs://ma-logistics/4649493c.csv', 'message': "Error while reading data, error message: Could not parse '27.981478ta2' as DOUBLE for field longitude (position 5) starting at location 298  with message 'Unable to parse'"}, 'errors': [{'reason': 'invalid', 'location': 'gs://ma-logistics/4649493c.csv', 'message': "Error while reading data, error message: Could not parse '27.981478ta2' as DOUBLE for field longitude (position 5) starting at location 298  with message 'Unable to parse'"}, {'reason': 'invalid', 'message': 'Error while reading data, error message: CSV processing encountered too many errors, giving up. Rows: 63; errors: 1; max bad: 0; error percent: 0'}, {'reason': 'invalidQuery', 'location': 'query', 'message': "Could not parse '27.981478ta2' as DOUBLE for field longitude (position 5) starting at location 298  with message 'Unable to parse'"}], 'state': 'DONE'}}
Traceback (most recent call last):
  File "/home/alieymsxxn/anaconda3/envs/airflow/lib/python3.7/site-packages/airflow/models/taskinstance.py", line 983, in _run_raw_task
    result = task_copy.execute(context=context)
  File "/home/alieymsxxn/anaconda3/envs/airflow/lib/python3.7/site-packages/airflow/contrib/operators/gcs_to_bq.py", line 288, in execute
    encryption_configuration=self.encryption_configuration)
  File "/home/alieymsxxn/anaconda3/envs/airflow/lib/python3.7/site-packages/airflow/contrib/hooks/bigquery_hook.py", line 1297, in run_load
    return self.run_with_configuration(configuration)
  File "/home/alieymsxxn/anaconda3/envs/airflow/lib/python3.7/site-packages/airflow/contrib/hooks/bigquery_hook.py", line 1344, in run_with_configuration
    format(job['status']['errorResult'], job))
Exception: BigQuery job failed. Final error was: {'reason': 'invalid', 'location': 'gs://ma-logistics/4649493c.csv', 'message': "Error while reading data, error message: Could not parse '27.981478ta2' as DOUBLE for field longitude (position 5) starting at location 298  with message 'Unable to parse'"}. The job was: {'kind': 'bigquery#job', 'etag': '0kVa6CkfZGFNoEjw+q67NA==', 'id': 'ma-airflow:asia-south1.job_Qe-8uiKwCp_Dfg-8WJyCUiRKzJlW', 'selfLink': 'https://bigquery.googleapis.com/bigquery/v2/projects/ma-airflow/jobs/job_Qe-8uiKwCp_Dfg-8WJyCUiRKzJlW?location=asia-south1', 'user_email': 'airflow@ma-airflow.iam.gserviceaccount.com', 'configuration': {'load': {'sourceUris': ['gs://ma-logistics/*'], 'destinationTable': {'projectId': 'ma-airflow', 'datasetId': 'analytics', 'tableId': 'history'}, 'createDisposition': 'CREATE_IF_NEEDED', 'writeDisposition': 'WRITE_APPEND', 'fieldDelimiter': ',', 'skipLeadingRows': 1, 'encoding': 'UTF-8', 'allowQuotedNewlines': False, 'sourceFormat': 'CSV', 'ignoreUnknownValues': False, 'autodetect': True}, 'jobType': 'LOAD'}, 'jobReference': {'projectId': 'ma-airflow', 'jobId': 'job_Qe-8uiKwCp_Dfg-8WJyCUiRKzJlW', 'location': 'asia-south1'}, 'statistics': {'creationTime': '1621202446777', 'startTime': '1621202446973', 'endTime': '1621202447917', 'load': {}, 'totalSlotMs': '158', 'reservation_id': 'default-pipeline'}, 'status': {'errorResult': {'reason': 'invalid', 'location': 'gs://ma-logistics/4649493c.csv', 'message': "Error while reading data, error message: Could not parse '27.981478ta2' as DOUBLE for field longitude (position 5) starting at location 298  with message 'Unable to parse'"}, 'errors': [{'reason': 'invalid', 'location': 'gs://ma-logistics/4649493c.csv', 'message': "Error while reading data, error message: Could not parse '27.981478ta2' as DOUBLE for field longitude (position 5) starting at location 298  with message 'Unable to parse'"}, {'reason': 'invalid', 'message': 'Error while reading data, error message: CSV processing encountered too many errors, giving up. Rows: 63; errors: 1; max bad: 0; error percent: 0'}, {'reason': 'invalidQuery', 'location': 'query', 'message': "Could not parse '27.981478ta2' as DOUBLE for field longitude (position 5) starting at location 298  with message 'Unable to parse'"}], 'state': 'DONE'}}
[2021-05-17 03:00:49,377] {taskinstance.py:1202} INFO - Marking task as FAILED.dag_id=bigquery_data_load, task_id=load_data, execution_date=20210516T210000, start_date=20210516T220041, end_date=20210516T220049
[2021-05-17 03:00:51,128] {logging_mixin.py:112} INFO - [2021-05-17 03:00:51,127] {local_task_job.py:103} INFO - Task exited with return code 1
[2021-05-17 03:11:52,021] {taskinstance.py:669} INFO - Dependencies all met for <TaskInstance: bigquery_data_load.load_data 2021-05-16T21:00:00+00:00 [queued]>
[2021-05-17 03:11:52,033] {taskinstance.py:669} INFO - Dependencies all met for <TaskInstance: bigquery_data_load.load_data 2021-05-16T21:00:00+00:00 [queued]>
[2021-05-17 03:11:52,033] {taskinstance.py:879} INFO - 
--------------------------------------------------------------------------------
[2021-05-17 03:11:52,033] {taskinstance.py:880} INFO - Starting attempt 1 of 1
[2021-05-17 03:11:52,033] {taskinstance.py:881} INFO - 
--------------------------------------------------------------------------------
[2021-05-17 03:11:52,081] {taskinstance.py:900} INFO - Executing <Task(GoogleCloudStorageToBigQueryOperator): load_data> on 2021-05-16T21:00:00+00:00
[2021-05-17 03:11:52,088] {standard_task_runner.py:53} INFO - Started process 38231 to run task
[2021-05-17 03:11:52,160] {logging_mixin.py:112} INFO - Running %s on host %s <TaskInstance: bigquery_data_load.load_data 2021-05-16T21:00:00+00:00 [running]> alieymsxxn
[2021-05-17 03:11:59,039] {taskinstance.py:1065} INFO - Marking task as SUCCESS.dag_id=bigquery_data_load, task_id=load_data, execution_date=20210516T210000, start_date=20210516T221152, end_date=20210516T221159
[2021-05-17 03:12:01,964] {logging_mixin.py:112} INFO - [2021-05-17 03:12:01,963] {local_task_job.py:103} INFO - Task exited with return code 0
