[2021-05-17 03:05:23,539] {taskinstance.py:669} INFO - Dependencies all met for <TaskInstance: bigquery_data_load.load_data 2021-05-16T22:05:04.459121+00:00 [queued]>
[2021-05-17 03:05:23,549] {taskinstance.py:669} INFO - Dependencies all met for <TaskInstance: bigquery_data_load.load_data 2021-05-16T22:05:04.459121+00:00 [queued]>
[2021-05-17 03:05:23,549] {taskinstance.py:879} INFO - 
--------------------------------------------------------------------------------
[2021-05-17 03:05:23,549] {taskinstance.py:880} INFO - Starting attempt 1 of 1
[2021-05-17 03:05:23,549] {taskinstance.py:881} INFO - 
--------------------------------------------------------------------------------
[2021-05-17 03:05:23,590] {taskinstance.py:900} INFO - Executing <Task(GoogleCloudStorageToBigQueryOperator): load_data> on 2021-05-16T22:05:04.459121+00:00
[2021-05-17 03:05:23,597] {standard_task_runner.py:53} INFO - Started process 37738 to run task
[2021-05-17 03:05:23,683] {logging_mixin.py:112} INFO - Running %s on host %s <TaskInstance: bigquery_data_load.load_data 2021-05-16T22:05:04.459121+00:00 [running]> alieymsxxn
[2021-05-17 03:05:30,519] {taskinstance.py:1145} ERROR - BigQuery job failed. Final error was: {'reason': 'invalid', 'location': 'gs://ma-logistics/4649493c.csv', 'message': "Error while reading data, error message: Could not parse '27.981478ta2' as DOUBLE for field longitude (position 5) starting at location 298  with message 'Unable to parse'"}. The job was: {'kind': 'bigquery#job', 'etag': 'sLeg784xmcjMqWPLr/D9Qw==', 'id': 'ma-airflow:asia-south1.job_U3gnyAAHS9r03yA28pCX1shduLNo', 'selfLink': 'https://bigquery.googleapis.com/bigquery/v2/projects/ma-airflow/jobs/job_U3gnyAAHS9r03yA28pCX1shduLNo?location=asia-south1', 'user_email': 'airflow@ma-airflow.iam.gserviceaccount.com', 'configuration': {'load': {'sourceUris': ['gs://ma-logistics/*'], 'destinationTable': {'projectId': 'ma-airflow', 'datasetId': 'analytics', 'tableId': 'history'}, 'createDisposition': 'CREATE_IF_NEEDED', 'writeDisposition': 'WRITE_APPEND', 'fieldDelimiter': ',', 'skipLeadingRows': 1, 'encoding': 'UTF-8', 'allowQuotedNewlines': False, 'sourceFormat': 'CSV', 'ignoreUnknownValues': False, 'autodetect': True}, 'jobType': 'LOAD'}, 'jobReference': {'projectId': 'ma-airflow', 'jobId': 'job_U3gnyAAHS9r03yA28pCX1shduLNo', 'location': 'asia-south1'}, 'statistics': {'creationTime': '1621202727875', 'startTime': '1621202728083', 'endTime': '1621202728961', 'load': {}, 'totalSlotMs': '142', 'reservation_id': 'default-pipeline'}, 'status': {'errorResult': {'reason': 'invalid', 'location': 'gs://ma-logistics/4649493c.csv', 'message': "Error while reading data, error message: Could not parse '27.981478ta2' as DOUBLE for field longitude (position 5) starting at location 298  with message 'Unable to parse'"}, 'errors': [{'reason': 'invalid', 'location': 'gs://ma-logistics/4649493c.csv', 'message': "Error while reading data, error message: Could not parse '27.981478ta2' as DOUBLE for field longitude (position 5) starting at location 298  with message 'Unable to parse'"}, {'reason': 'invalid', 'message': 'Error while reading data, error message: CSV processing encountered too many errors, giving up. Rows: 63; errors: 1; max bad: 0; error percent: 0'}, {'reason': 'invalidQuery', 'location': 'query', 'message': "Could not parse '27.981478ta2' as DOUBLE for field longitude (position 5) starting at location 298  with message 'Unable to parse'"}], 'state': 'DONE'}}
Traceback (most recent call last):
  File "/home/alieymsxxn/anaconda3/envs/airflow/lib/python3.7/site-packages/airflow/models/taskinstance.py", line 983, in _run_raw_task
    result = task_copy.execute(context=context)
  File "/home/alieymsxxn/anaconda3/envs/airflow/lib/python3.7/site-packages/airflow/contrib/operators/gcs_to_bq.py", line 288, in execute
    encryption_configuration=self.encryption_configuration)
  File "/home/alieymsxxn/anaconda3/envs/airflow/lib/python3.7/site-packages/airflow/contrib/hooks/bigquery_hook.py", line 1297, in run_load
    return self.run_with_configuration(configuration)
  File "/home/alieymsxxn/anaconda3/envs/airflow/lib/python3.7/site-packages/airflow/contrib/hooks/bigquery_hook.py", line 1344, in run_with_configuration
    format(job['status']['errorResult'], job))
Exception: BigQuery job failed. Final error was: {'reason': 'invalid', 'location': 'gs://ma-logistics/4649493c.csv', 'message': "Error while reading data, error message: Could not parse '27.981478ta2' as DOUBLE for field longitude (position 5) starting at location 298  with message 'Unable to parse'"}. The job was: {'kind': 'bigquery#job', 'etag': 'sLeg784xmcjMqWPLr/D9Qw==', 'id': 'ma-airflow:asia-south1.job_U3gnyAAHS9r03yA28pCX1shduLNo', 'selfLink': 'https://bigquery.googleapis.com/bigquery/v2/projects/ma-airflow/jobs/job_U3gnyAAHS9r03yA28pCX1shduLNo?location=asia-south1', 'user_email': 'airflow@ma-airflow.iam.gserviceaccount.com', 'configuration': {'load': {'sourceUris': ['gs://ma-logistics/*'], 'destinationTable': {'projectId': 'ma-airflow', 'datasetId': 'analytics', 'tableId': 'history'}, 'createDisposition': 'CREATE_IF_NEEDED', 'writeDisposition': 'WRITE_APPEND', 'fieldDelimiter': ',', 'skipLeadingRows': 1, 'encoding': 'UTF-8', 'allowQuotedNewlines': False, 'sourceFormat': 'CSV', 'ignoreUnknownValues': False, 'autodetect': True}, 'jobType': 'LOAD'}, 'jobReference': {'projectId': 'ma-airflow', 'jobId': 'job_U3gnyAAHS9r03yA28pCX1shduLNo', 'location': 'asia-south1'}, 'statistics': {'creationTime': '1621202727875', 'startTime': '1621202728083', 'endTime': '1621202728961', 'load': {}, 'totalSlotMs': '142', 'reservation_id': 'default-pipeline'}, 'status': {'errorResult': {'reason': 'invalid', 'location': 'gs://ma-logistics/4649493c.csv', 'message': "Error while reading data, error message: Could not parse '27.981478ta2' as DOUBLE for field longitude (position 5) starting at location 298  with message 'Unable to parse'"}, 'errors': [{'reason': 'invalid', 'location': 'gs://ma-logistics/4649493c.csv', 'message': "Error while reading data, error message: Could not parse '27.981478ta2' as DOUBLE for field longitude (position 5) starting at location 298  with message 'Unable to parse'"}, {'reason': 'invalid', 'message': 'Error while reading data, error message: CSV processing encountered too many errors, giving up. Rows: 63; errors: 1; max bad: 0; error percent: 0'}, {'reason': 'invalidQuery', 'location': 'query', 'message': "Could not parse '27.981478ta2' as DOUBLE for field longitude (position 5) starting at location 298  with message 'Unable to parse'"}], 'state': 'DONE'}}
[2021-05-17 03:05:30,524] {taskinstance.py:1202} INFO - Marking task as FAILED.dag_id=bigquery_data_load, task_id=load_data, execution_date=20210516T220504, start_date=20210516T220523, end_date=20210516T220530
[2021-05-17 03:05:33,505] {logging_mixin.py:112} INFO - [2021-05-17 03:05:33,504] {local_task_job.py:103} INFO - Task exited with return code 1
