[2021-05-17 03:12:59,023] {taskinstance.py:669} INFO - Dependencies all met for <TaskInstance: bigquery_data_load.move_files 2021-05-16T22:11:19.682479+00:00 [queued]>
[2021-05-17 03:12:59,036] {taskinstance.py:669} INFO - Dependencies all met for <TaskInstance: bigquery_data_load.move_files 2021-05-16T22:11:19.682479+00:00 [queued]>
[2021-05-17 03:12:59,036] {taskinstance.py:879} INFO - 
--------------------------------------------------------------------------------
[2021-05-17 03:12:59,036] {taskinstance.py:880} INFO - Starting attempt 1 of 1
[2021-05-17 03:12:59,036] {taskinstance.py:881} INFO - 
--------------------------------------------------------------------------------
[2021-05-17 03:12:59,074] {taskinstance.py:900} INFO - Executing <Task(PythonOperator): move_files> on 2021-05-16T22:11:19.682479+00:00
[2021-05-17 03:12:59,079] {standard_task_runner.py:53} INFO - Started process 38311 to run task
[2021-05-17 03:12:59,159] {logging_mixin.py:112} INFO - Running %s on host %s <TaskInstance: bigquery_data_load.move_files 2021-05-16T22:11:19.682479+00:00 [running]> alieymsxxn
[2021-05-17 03:13:00,384] {taskinstance.py:1145} ERROR - 404 POST https://storage.googleapis.com/storage/v1/b/ma-logistics/o/4649493c.csv/copyTo/b/ma-bklogistics/o/20210516T221119%2F4649493c.csv?prettyPrint=false: No such object: ma-logistics/4649493c.csv
Traceback (most recent call last):
  File "/home/alieymsxxn/anaconda3/envs/airflow/lib/python3.7/site-packages/airflow/models/taskinstance.py", line 983, in _run_raw_task
    result = task_copy.execute(context=context)
  File "/home/alieymsxxn/anaconda3/envs/airflow/lib/python3.7/site-packages/airflow/operators/python_operator.py", line 113, in execute
    return_value = self.execute_callable()
  File "/home/alieymsxxn/anaconda3/envs/airflow/lib/python3.7/site-packages/airflow/operators/python_operator.py", line 118, in execute_callable
    return self.python_callable(*self.op_args, **self.op_kwargs)
  File "/home/alieymsxxn/Documents/Projects/airflow/airflow_home/dags/bigquery_data_load.py", line 34, in move_objects
    hook.copy(source_bucket, storage_object, destination_bucket, destination_object)
  File "/home/alieymsxxn/anaconda3/envs/airflow/lib/python3.7/site-packages/airflow/contrib/hooks/gcs_hook.py", line 94, in copy
    new_name=destination_object)
  File "/home/alieymsxxn/anaconda3/envs/airflow/lib/python3.7/site-packages/google/cloud/storage/bucket.py", line 1993, in copy_blob
    retry=retry,
  File "/home/alieymsxxn/anaconda3/envs/airflow/lib/python3.7/site-packages/google/cloud/storage/_http.py", line 78, in api_request
    return call()
  File "/home/alieymsxxn/anaconda3/envs/airflow/lib/python3.7/site-packages/google/cloud/_http.py", line 483, in api_request
    raise exceptions.from_http_response(response)
google.api_core.exceptions.NotFound: 404 POST https://storage.googleapis.com/storage/v1/b/ma-logistics/o/4649493c.csv/copyTo/b/ma-bklogistics/o/20210516T221119%2F4649493c.csv?prettyPrint=false: No such object: ma-logistics/4649493c.csv
[2021-05-17 03:13:00,388] {taskinstance.py:1202} INFO - Marking task as FAILED.dag_id=bigquery_data_load, task_id=move_files, execution_date=20210516T221119, start_date=20210516T221259, end_date=20210516T221300
[2021-05-17 03:13:08,983] {logging_mixin.py:112} INFO - [2021-05-17 03:13:08,983] {local_task_job.py:103} INFO - Task exited with return code 1
