[2021-05-17 02:00:19,273] {taskinstance.py:669} INFO - Dependencies all met for <TaskInstance: bigquery_data_load.load_data 2021-05-16T20:00:00+00:00 [queued]>
[2021-05-17 02:00:19,283] {taskinstance.py:669} INFO - Dependencies all met for <TaskInstance: bigquery_data_load.load_data 2021-05-16T20:00:00+00:00 [queued]>
[2021-05-17 02:00:19,283] {taskinstance.py:879} INFO - 
--------------------------------------------------------------------------------
[2021-05-17 02:00:19,283] {taskinstance.py:880} INFO - Starting attempt 1 of 1
[2021-05-17 02:00:19,283] {taskinstance.py:881} INFO - 
--------------------------------------------------------------------------------
[2021-05-17 02:00:19,322] {taskinstance.py:900} INFO - Executing <Task(GoogleCloudStorageToBigQueryOperator): load_data> on 2021-05-16T20:00:00+00:00
[2021-05-17 02:00:19,330] {standard_task_runner.py:53} INFO - Started process 33602 to run task
[2021-05-17 02:00:19,416] {logging_mixin.py:112} INFO - Running %s on host %s <TaskInstance: bigquery_data_load.load_data 2021-05-16T20:00:00+00:00 [running]> alieymsxxn
[2021-05-17 02:00:26,488] {taskinstance.py:1145} ERROR - BigQuery job failed. Final error was: {'reason': 'notFound', 'message': 'Not found: Uris gs://ma-logistics/*'}. The job was: {'kind': 'bigquery#job', 'etag': 'InBp9zCPdaG8Odw3MqXYVg==', 'id': 'ma-airflow:asia-south1.job_jzpM_a1q5L8DUMLgsDBKPLo8GT0p', 'selfLink': 'https://bigquery.googleapis.com/bigquery/v2/projects/ma-airflow/jobs/job_jzpM_a1q5L8DUMLgsDBKPLo8GT0p?location=asia-south1', 'user_email': 'airflow@ma-airflow.iam.gserviceaccount.com', 'configuration': {'load': {'sourceUris': ['gs://ma-logistics/*'], 'destinationTable': {'projectId': 'ma-airflow', 'datasetId': 'analytics', 'tableId': 'history'}, 'createDisposition': 'CREATE_IF_NEEDED', 'writeDisposition': 'WRITE_APPEND', 'fieldDelimiter': ',', 'skipLeadingRows': 1, 'encoding': 'UTF-8', 'allowQuotedNewlines': False, 'sourceFormat': 'CSV', 'ignoreUnknownValues': False, 'autodetect': True}, 'jobType': 'LOAD'}, 'jobReference': {'projectId': 'ma-airflow', 'jobId': 'job_jzpM_a1q5L8DUMLgsDBKPLo8GT0p', 'location': 'asia-south1'}, 'statistics': {'creationTime': '1621198823815', 'startTime': '1621198824070', 'endTime': '1621198824172'}, 'status': {'errorResult': {'reason': 'notFound', 'message': 'Not found: Uris gs://ma-logistics/*'}, 'errors': [{'reason': 'notFound', 'message': 'Not found: Uris gs://ma-logistics/*'}], 'state': 'DONE'}}
Traceback (most recent call last):
  File "/home/alieymsxxn/anaconda3/envs/airflow/lib/python3.7/site-packages/airflow/models/taskinstance.py", line 983, in _run_raw_task
    result = task_copy.execute(context=context)
  File "/home/alieymsxxn/anaconda3/envs/airflow/lib/python3.7/site-packages/airflow/contrib/operators/gcs_to_bq.py", line 288, in execute
    encryption_configuration=self.encryption_configuration)
  File "/home/alieymsxxn/anaconda3/envs/airflow/lib/python3.7/site-packages/airflow/contrib/hooks/bigquery_hook.py", line 1297, in run_load
    return self.run_with_configuration(configuration)
  File "/home/alieymsxxn/anaconda3/envs/airflow/lib/python3.7/site-packages/airflow/contrib/hooks/bigquery_hook.py", line 1344, in run_with_configuration
    format(job['status']['errorResult'], job))
Exception: BigQuery job failed. Final error was: {'reason': 'notFound', 'message': 'Not found: Uris gs://ma-logistics/*'}. The job was: {'kind': 'bigquery#job', 'etag': 'InBp9zCPdaG8Odw3MqXYVg==', 'id': 'ma-airflow:asia-south1.job_jzpM_a1q5L8DUMLgsDBKPLo8GT0p', 'selfLink': 'https://bigquery.googleapis.com/bigquery/v2/projects/ma-airflow/jobs/job_jzpM_a1q5L8DUMLgsDBKPLo8GT0p?location=asia-south1', 'user_email': 'airflow@ma-airflow.iam.gserviceaccount.com', 'configuration': {'load': {'sourceUris': ['gs://ma-logistics/*'], 'destinationTable': {'projectId': 'ma-airflow', 'datasetId': 'analytics', 'tableId': 'history'}, 'createDisposition': 'CREATE_IF_NEEDED', 'writeDisposition': 'WRITE_APPEND', 'fieldDelimiter': ',', 'skipLeadingRows': 1, 'encoding': 'UTF-8', 'allowQuotedNewlines': False, 'sourceFormat': 'CSV', 'ignoreUnknownValues': False, 'autodetect': True}, 'jobType': 'LOAD'}, 'jobReference': {'projectId': 'ma-airflow', 'jobId': 'job_jzpM_a1q5L8DUMLgsDBKPLo8GT0p', 'location': 'asia-south1'}, 'statistics': {'creationTime': '1621198823815', 'startTime': '1621198824070', 'endTime': '1621198824172'}, 'status': {'errorResult': {'reason': 'notFound', 'message': 'Not found: Uris gs://ma-logistics/*'}, 'errors': [{'reason': 'notFound', 'message': 'Not found: Uris gs://ma-logistics/*'}], 'state': 'DONE'}}
[2021-05-17 02:00:26,495] {taskinstance.py:1202} INFO - Marking task as FAILED.dag_id=bigquery_data_load, task_id=load_data, execution_date=20210516T200000, start_date=20210516T210019, end_date=20210516T210026
[2021-05-17 02:00:29,239] {logging_mixin.py:112} INFO - [2021-05-17 02:00:29,238] {local_task_job.py:103} INFO - Task exited with return code 1
[2021-05-17 03:00:25,627] {taskinstance.py:669} INFO - Dependencies all met for <TaskInstance: bigquery_data_load.load_data 2021-05-16T20:00:00+00:00 [queued]>
[2021-05-17 03:00:25,644] {taskinstance.py:669} INFO - Dependencies all met for <TaskInstance: bigquery_data_load.load_data 2021-05-16T20:00:00+00:00 [queued]>
[2021-05-17 03:00:25,644] {taskinstance.py:879} INFO - 
--------------------------------------------------------------------------------
[2021-05-17 03:00:25,644] {taskinstance.py:880} INFO - Starting attempt 1 of 1
[2021-05-17 03:00:25,644] {taskinstance.py:881} INFO - 
--------------------------------------------------------------------------------
[2021-05-17 03:00:25,680] {taskinstance.py:900} INFO - Executing <Task(GoogleCloudStorageToBigQueryOperator): load_data> on 2021-05-16T20:00:00+00:00
[2021-05-17 03:00:25,686] {standard_task_runner.py:53} INFO - Started process 37406 to run task
[2021-05-17 03:00:25,760] {logging_mixin.py:112} INFO - Running %s on host %s <TaskInstance: bigquery_data_load.load_data 2021-05-16T20:00:00+00:00 [running]> alieymsxxn
[2021-05-17 03:00:32,941] {taskinstance.py:1145} ERROR - BigQuery job failed. Final error was: {'reason': 'invalid', 'location': 'gs://ma-logistics/4649493c.csv', 'message': "Error while reading data, error message: Could not parse '27.981478ta2' as DOUBLE for field longitude (position 5) starting at location 298  with message 'Unable to parse'"}. The job was: {'kind': 'bigquery#job', 'etag': '6DWE1XpUDD1Tph93tUXoRw==', 'id': 'ma-airflow:asia-south1.job_JFUrOw0vjxiAwf8oMV1U87j0FLAg', 'selfLink': 'https://bigquery.googleapis.com/bigquery/v2/projects/ma-airflow/jobs/job_JFUrOw0vjxiAwf8oMV1U87j0FLAg?location=asia-south1', 'user_email': 'airflow@ma-airflow.iam.gserviceaccount.com', 'configuration': {'load': {'sourceUris': ['gs://ma-logistics/*'], 'destinationTable': {'projectId': 'ma-airflow', 'datasetId': 'analytics', 'tableId': 'history'}, 'createDisposition': 'CREATE_IF_NEEDED', 'writeDisposition': 'WRITE_APPEND', 'fieldDelimiter': ',', 'skipLeadingRows': 1, 'encoding': 'UTF-8', 'allowQuotedNewlines': False, 'sourceFormat': 'CSV', 'ignoreUnknownValues': False, 'autodetect': True}, 'jobType': 'LOAD'}, 'jobReference': {'projectId': 'ma-airflow', 'jobId': 'job_JFUrOw0vjxiAwf8oMV1U87j0FLAg', 'location': 'asia-south1'}, 'statistics': {'creationTime': '1621202430227', 'startTime': '1621202430487', 'endTime': '1621202431714', 'load': {}, 'totalSlotMs': '212', 'reservation_id': 'default-pipeline'}, 'status': {'errorResult': {'reason': 'invalid', 'location': 'gs://ma-logistics/4649493c.csv', 'message': "Error while reading data, error message: Could not parse '27.981478ta2' as DOUBLE for field longitude (position 5) starting at location 298  with message 'Unable to parse'"}, 'errors': [{'reason': 'invalid', 'location': 'gs://ma-logistics/4649493c.csv', 'message': "Error while reading data, error message: Could not parse '27.981478ta2' as DOUBLE for field longitude (position 5) starting at location 298  with message 'Unable to parse'"}, {'reason': 'invalid', 'message': 'Error while reading data, error message: CSV processing encountered too many errors, giving up. Rows: 63; errors: 1; max bad: 0; error percent: 0'}, {'reason': 'invalidQuery', 'location': 'query', 'message': "Could not parse '27.981478ta2' as DOUBLE for field longitude (position 5) starting at location 298  with message 'Unable to parse'"}], 'state': 'DONE'}}
Traceback (most recent call last):
  File "/home/alieymsxxn/anaconda3/envs/airflow/lib/python3.7/site-packages/airflow/models/taskinstance.py", line 983, in _run_raw_task
    result = task_copy.execute(context=context)
  File "/home/alieymsxxn/anaconda3/envs/airflow/lib/python3.7/site-packages/airflow/contrib/operators/gcs_to_bq.py", line 288, in execute
    encryption_configuration=self.encryption_configuration)
  File "/home/alieymsxxn/anaconda3/envs/airflow/lib/python3.7/site-packages/airflow/contrib/hooks/bigquery_hook.py", line 1297, in run_load
    return self.run_with_configuration(configuration)
  File "/home/alieymsxxn/anaconda3/envs/airflow/lib/python3.7/site-packages/airflow/contrib/hooks/bigquery_hook.py", line 1344, in run_with_configuration
    format(job['status']['errorResult'], job))
Exception: BigQuery job failed. Final error was: {'reason': 'invalid', 'location': 'gs://ma-logistics/4649493c.csv', 'message': "Error while reading data, error message: Could not parse '27.981478ta2' as DOUBLE for field longitude (position 5) starting at location 298  with message 'Unable to parse'"}. The job was: {'kind': 'bigquery#job', 'etag': '6DWE1XpUDD1Tph93tUXoRw==', 'id': 'ma-airflow:asia-south1.job_JFUrOw0vjxiAwf8oMV1U87j0FLAg', 'selfLink': 'https://bigquery.googleapis.com/bigquery/v2/projects/ma-airflow/jobs/job_JFUrOw0vjxiAwf8oMV1U87j0FLAg?location=asia-south1', 'user_email': 'airflow@ma-airflow.iam.gserviceaccount.com', 'configuration': {'load': {'sourceUris': ['gs://ma-logistics/*'], 'destinationTable': {'projectId': 'ma-airflow', 'datasetId': 'analytics', 'tableId': 'history'}, 'createDisposition': 'CREATE_IF_NEEDED', 'writeDisposition': 'WRITE_APPEND', 'fieldDelimiter': ',', 'skipLeadingRows': 1, 'encoding': 'UTF-8', 'allowQuotedNewlines': False, 'sourceFormat': 'CSV', 'ignoreUnknownValues': False, 'autodetect': True}, 'jobType': 'LOAD'}, 'jobReference': {'projectId': 'ma-airflow', 'jobId': 'job_JFUrOw0vjxiAwf8oMV1U87j0FLAg', 'location': 'asia-south1'}, 'statistics': {'creationTime': '1621202430227', 'startTime': '1621202430487', 'endTime': '1621202431714', 'load': {}, 'totalSlotMs': '212', 'reservation_id': 'default-pipeline'}, 'status': {'errorResult': {'reason': 'invalid', 'location': 'gs://ma-logistics/4649493c.csv', 'message': "Error while reading data, error message: Could not parse '27.981478ta2' as DOUBLE for field longitude (position 5) starting at location 298  with message 'Unable to parse'"}, 'errors': [{'reason': 'invalid', 'location': 'gs://ma-logistics/4649493c.csv', 'message': "Error while reading data, error message: Could not parse '27.981478ta2' as DOUBLE for field longitude (position 5) starting at location 298  with message 'Unable to parse'"}, {'reason': 'invalid', 'message': 'Error while reading data, error message: CSV processing encountered too many errors, giving up. Rows: 63; errors: 1; max bad: 0; error percent: 0'}, {'reason': 'invalidQuery', 'location': 'query', 'message': "Could not parse '27.981478ta2' as DOUBLE for field longitude (position 5) starting at location 298  with message 'Unable to parse'"}], 'state': 'DONE'}}
[2021-05-17 03:00:32,947] {taskinstance.py:1202} INFO - Marking task as FAILED.dag_id=bigquery_data_load, task_id=load_data, execution_date=20210516T200000, start_date=20210516T220025, end_date=20210516T220032
[2021-05-17 03:00:35,580] {logging_mixin.py:112} INFO - [2021-05-17 03:00:35,579] {local_task_job.py:103} INFO - Task exited with return code 1
